<?xml version="1.0" encoding="utf-8"?>
<robot name="rexarm">
    <!--
    rexarm_description: URDF for the Rexarm.
    Copyright (C) 2019 Nathan Brown, Martin Deegan, Gregory Meyer, and Zhihao Ruan

    This program is free software: you can redistribute it and/or modify
    it under the terms of the GNU Affero General Public License as published
    by the Free Software Foundation, either version 3 of the License, or
    (at your option) any later version.

    This program is distributed in the hope that it will be useful,
    but WITHOUT ANY WARRANTY; without even the implied warranty of
    MERCHANTABILITY or FITNESS FOR A PARTICULAR PURPOSE.  See the
    GNU Affero General Public License for more details.

    You should have received a copy of the GNU Affero General Public License
    along with this program.  If not, see <http://www.gnu.org/licenses/>.
    -->

    <link name="base_link"/>
    <link name="base_servo_link"/>
    <link name="shoulder_servo_link"/>
    <link name="elbow_servo_link"/>
    <link name="wrist_servo_link"/>
    <link name="wrist_rotate_servo_link"/>
    <link name="gripper_servo_link"/>
    <link name="gripper_center_link"/>

    <joint name="base_servo" type="continuous">
        <parent link="base_link"/>
        <child link="base_servo_link"/>
        <origin rpy="0.0 0.0 0.0" xyz="0.0 -0.0015 0.0715"/>
        <axis xyz="0.0 0.0 1.0"/>
    </joint>

    <joint name="shoulder_servo" type="continuous">
        <parent link="base_servo_link"/>
        <child link="shoulder_servo_link"/>
        <origin rpy="0.0 0.0 0.0" xyz="0.0 0.0 0.045"/>
        <axis xyz="0.0 1.0 0.0"/>
    </joint>

    <joint name="elbow_servo" type="continuous">
        <parent link="shoulder_servo_link"/>
        <child link="elbow_servo_link"/>
        <origin rpy="0.0 0.0 0.0" xyz="0.0 0.0 0.1"/>
        <axis xyz="0.0 1.0 0.0"/>
    </joint>

    <joint name="wrist_servo" type="continuous">
        <parent link="elbow_servo_link"/>
        <child link="wrist_servo_link"/>
        <origin rpy="0.0 0.0 0.0" xyz="0.0 0.0 0.1"/>
        <axis xyz="0.0 1.0 0.0"/>
    </joint>

    <joint name="wrist_rotate_servo" type="continuous">
        <parent link="wrist_servo_link"/>
        <child link="wrist_rotate_servo_link"/>
        <origin rpy="0.0 0.0 0.0" xyz="0.0 -0.0125 0.08"/>
        <axis xyz="0.0 0.0 1.0"/>
    </joint>

    <joint name="gripper_servo" type="continuous">
        <parent link="wrist_rotate_servo_link"/>
        <child link="gripper_servo_link"/>
        <origin rpy="0.0 0.0 0.0" xyz="0.0 -0.013 0.019"/>
        <axis xyz="1.0 0.0 0.0"/>
    </joint>

    <joint name="gripper_center" type="fixed">
        <parent link="wrist_rotate_servo_link"/>
        <child link="gripper_center_link"/>
        <origin rpy="0.0 -1.5707963267948966 0.0" xyz="0.0 -0.005 0.07"/>
    </joint>
</robot>
