<!--
rexarm_description: URDF for the Rexarm.
Copyright (C) 2019 Nathan Brown, Martin Deegan, Gregory Meyer, and Zhihao Ruan

This program is free software: you can redistribute it and/or modify
it under the terms of the GNU Affero General Public License as published
by the Free Software Foundation, either version 3 of the License, or
(at your option) any later version.

This program is distributed in the hope that it will be useful,
but WITHOUT ANY WARRANTY; without even the implied warranty of
MERCHANTABILITY or FITNESS FOR A PARTICULAR PURPOSE.  See the
GNU Affero General Public License for more details.

You should have received a copy of the GNU Affero General Public License
along with this program.  If not, see <http://www.gnu.org/licenses/>.
-->

<?xml version="1.0" encoding="utf-8"?>
<robot name="rexarm">
    <!-- mx-28 dimensions: 3.5cm short axis, 5cm long axis, 3cm tall (mounting
         plate to mounting plate), 1.1cm from front face to horn axis -->

    <material name="black">
        <color rgba="0.0 0.0 0.0 1.0"/>
    </material>

    <material name="blue">
        <color rgba="0.0 0.0 0.8 1.0"/>
    </material>

    <!-- center of the board -->
    <link name="base_link"/>

    <!-- 3d printed base that the base servo sits on -->
    <link name="base_block">
        <visual>
            <geometry>
                <!-- 5cm x 4cm x 3.87cm -->
                <box size="0.05 0.04 0.0387"/>
            </geometry>
            <material name="blue"/>
        </visual>
    </link>

    <joint name="base_block_joint" type="fixed">
        <parent link="base_link"/>
        <child link="base_block"/>
        <!-- (1.3cm, -1.5mm, 1.935cm) -->
        <origin rpy="0.0 0.0 0.0" xyz="0.013 -0.0015 0.01935"/>
    </joint>

    <!-- base mx-28 -->
    <link name="base_servo">
        <visual>
            <geometry>
                <!-- 5cm x 3.5cm x 3cm -->
                <box size="0.05 0.035 0.03"/>
            </geometry>
            <material name="black"/>
        </visual>
    </link>

    <joint name="base_servo_joint" type="fixed">
        <parent link="base_block"/>
        <child link="base_servo"/>
        <!-- (0cm, 0cm, 3.435cm) -->
        <origin rpy="0.0 0.0 0.0" xyz="0.0 0.0 0.03435"/>
    </joint>

    <!-- shoulder mx-28 -->
    <link name="shoulder_servo">
        <visual>
            <geometry>
                <!-- 3.5cm x 3cm x 5cm -->
                <box size="0.035 0.03 0.05"/>
            </geometry>
            <material name="black"/>
        </visual>
    </link>

    <joint name="shoulder_servo_joint" type="continuous">
        <parent link="base_servo"/>
        <child link="shoulder_servo"/>
        <!-- (-1.3cm, 0cm, 4.84cm) -->
        <origin rpy="0.0 0.0 0.0" xyz="-0.013 0.0 0.0484"/>
        <axis xyz="0.0 0.0 1.0"/>
    </joint>

    <!-- shoulder horn -->
    <link name="shoulder_horn">
        <visual>
            <geometry>
                <!-- 3.8cm x 5.3cm x 9cm -->
                <box size="0.038 0.053 0.09"/>
            </geometry>
            <material name="blue"/>
        </visual>
    </link>

    <joint name="shoulder_horn_joint" type="continuous">
        <parent link="shoulder_servo"/>
        <child link="shoulder_horn"/>

        <!-- (0cm, 0cm, 2.9cm) -->
        <origin rpy="0.0 0.0 0.0" xyz="0.0 0.0 0.029"/>
        <axis xyz="0.0 1.0 0.0"/>
    </joint>

    <!-- elbow mx-28 -->
    <link name="elbow_servo">
        <visual>
            <geometry>
                <!-- 3.5cm x 3cm x 5cm -->
                <box size="0.035 0.03 0.05"/>
            </geometry>
            <material name="black"/>
        </visual>
    </link>

    <joint name="elbow_servo_joint" type="fixed">
        <parent link="shoulder_horn"/>
        <child link="elbow_servo"/>

        <!-- (0cm, 0cm, 5cm) -->
        <origin rpy="0.0 0.0 0.0" xyz="0.0 0.0 0.05"/>
    </joint>
</robot>
