<?xml version="1.0" encoding="utf-8"?>
<robot name="goat">
    <!-- mx-28 dimensions: 3.5cm short axis, 5cm long axis, 3cm tall (mounting
         plate to mounting plate), 1.1cm from front face to horn axis -->

    <material name="black">
        <color rgba="0.0 0.0 0.0 1.0"/>
    </material>

    <material name="blue">
        <color rgba="0.0 0.0 0.8 1.0"/>
    </material>

    <!-- center of the board -->
    <link name="base_link"/>

    <!-- 3d printed base that the base servo sits on -->
    <link name="base_block">
        <visual>
            <geometry>
                <!-- 5cm x 4cm x 3.87cm -->
                <box size="0.05 0.04 0.0387"/>
            </geometry>
            <material name="blue"/>
        </visual>
    </link>

    <joint name="base_block_joint" type="fixed">
        <parent link="base_link"/>
        <child link="base_block"/>
        <!-- (1.3cm, -1.5mm, 1.935cm) -->
        <origin rpy="0.0 0.0 0.0" xyz="0.013 -0.0015 0.01935"/>
    </joint>

    <!-- base mx-28 -->
    <link name="base_servo">
        <visual>
            <geometry>
                <!-- 5cm x 3.5cm x 3cm -->
                <box size="0.05 0.035 0.03"/>
            </geometry>
            <material name="black"/>
        </visual>
    </link>

    <joint name="base_servo_joint" type="fixed">
        <parent link="base_block"/>
        <child link="base_servo"/>
        <!-- (0cm, 0cm, 1.935cm + 1.5cm = 3.435cm) -->
        <origin rpy="0.0 0.0 0.0" xyz="0.0 0.0 0.03435"/>
    </joint>

    <!-- shoulder mx-28 -->
    <link name="shoulder_servo">
        <visual>
            <geometry>
                <!-- 3.5cm x 3cm x 5cm -->
                <box size="0.035 0.03 0.05"/>
            </geometry>
            <material name="black"/>
        </visual>
    </link>

    <joint name="shoulder_servo_joint" type="continuous">
        <parent link="base_servo"/>
        <child link="shoulder_servo"/>
        <!-- (-1.3cm, 0cm, (5.9mm (base servomounting plate to horn top) + 2.5mm (horn top to bottom of shoulder servo) + (5cm + 3cm) / 2 = 4.84cm) -->
        <origin rpy="0.0 0.0 0.0" xyz="-0.013 0.0 0.0484"/>
        <axis xyz="0.0 1.0 0.0"/>
    </joint>
</robot>
